Workbook

Sheet RETAIL
A1: 1 | B1: 2 | C1: 3 | D1: 4 | E1: 5 | F1: 6 | G1: 7 | H1: 8 | I1: 9 | J1: 10 | K1: 11 | L1: 12 | M1: 13 | N1: 14 | O1: 15 | P1: 16 | Q1: 17 | R1: 18 | S1: 19 | T1: 20 | U1: 21 | V1: 22 | W1: 23 | X1: 24 | Y1: 25 | Z1: 26 | AA1: 27 | AB1: 28 | AC1: 29 | AD1: 30 | AE1: 31 | AF1: 32 | AG1: 33 | AH1: 34 | AI1: 35 | AJ1: 36 | AK1: 37 | AL1: 38 | AM1: 39 | AN1: 40 | AO1: 41 | AP1: 42 | AQ1: 43 | AR1: 44 | AS1: 45 | AT1: 46 | AU1: 47 | AV1: 48 | AW1: 49 | AX1: 50 | AY1: 51 | AZ1: 52 | BA1: 53 | BB1: 54 | BC1: 55 | BD1: 56 | BE1: 57 | BF1: 58 | BG1: 59 | BH1: 60 | BI1: 61 | BJ1: 62 | BK1: 63 | BL1: 64 | BM1: 65 | BN1: 66 | BO1: 67 | BP1: 68 | BQ1: 69
A2: 受注番号 | B2: 納品先コード | C2: 納品先名 | D2: 商品コード | E2: 商品名 | F2: Brand | G2: NWA | H2: BULK | I2: BULK | J2: BULK | K2: BULK | L2: BULK | M2: BULK | N2: BULK | O2: BULK | P2: BULK | Q2: BULK | R2: BULK | S2: BULK | T2: BULK | U2: BULK | V2: BULK | W2: BULK | X2: BULK | Y2: BULK | Z2: BULK | AA2: BULK | AB2: BULK | AC2: 現在庫 | AD2: 現在庫 | AE2: 現在庫 | AF2: 現在庫 | AG2: 現在庫 | AH2: 現在庫 | AI2: 現在庫 | AJ2: 現在庫 | AK2: 現在庫 | AL2: 現在庫 | AM2: 現在庫 | AN2: 現在庫 | AO2: 現在庫 | AP2: 現在庫 | AQ2: 現在庫 | AR2: 現在庫 | AS2: 現在庫 | AT2: 現在庫 | AU2: 現在庫 | AV2: 現在庫 | AW2: 出荷指示数 | AX2: 出荷指示数 | AY2: 出荷指示数 | AZ2: 出荷指示数 | BA2: 出荷指示数 | BB2: 出荷指示数 | BC2: 出荷指示数 | BD2: 出荷指示数 | BE2: 出荷指示数 | BF2: 出荷指示数 | BG2: 出荷指示数 | BH2: 出荷指示数 | BI2: 出荷指示数 | BJ2: 出荷指示数 | BK2: 出荷指示数 | BL2: 出荷指示数 | BM2: 出荷指示数 | BN2: 出荷指示数 | BO2: 出荷指示数 | BP2: 出荷指示数 | BQ2: 出荷予定日
G3: NWA | H3: 納品先BULK | I3: 201050 | J3: 201127 | K3: 201223 | L3: 201236 | M3: 201268 | N3: 201499 | O3: 201549 | P3: 201684 | Q3: 201703 | R3: 201716 | S3: 201720 | T3: 201738 | U3: 201762 | AC3: 201050 | AD3: 201127 | AE3: 201223 | AF3: 201236 | AG3: 201268 | AH3: 201499 | AI3: 201549 | AJ3: 201684 | AK3: 201703 | AL3: 201716 | AM3: 201720 | AN3: 201738 | AO3: 201762 | AW3: 201050 | AX3: 201127 | AY3: 201223 | AZ3: 201236 | BA3: 201268 | BB3: 201499 | BC3: 201549 | BD3: 201684 | BE3: 201703 | BF3: 201716 | BG3: 201720 | BH3: 201738 | BI3: 201762
G4: NWA | H4: 納品先BULK | I4: ZOZO | J4: 名古屋 | K4: 丸井web | L4: YSEC | M4: TOKYO | N4: ルクア大阪 | O4: ヒュッテ | P4: 京王新宿 | Q4: 6142 | R4: 玉川高島屋 | S4: NODE | T4: 大丸心斎橋 | U4: NARITA | AC4: ZOZO | AD4: 名古屋 | AE4: 丸井web | AF4: YSEC | AG4: TOKYO | AH4: ルクア大阪 | AI4: ヒュッテ | AJ4: 京王新宿 | AK4: 6142 | AL4: 玉川高島屋 | AM4: NODE | AN4: 大丸心斎橋 | AO4: NARITA | AW4: ZOZO | AX4: 名古屋 | AY4: 丸井web | AZ4: YSEC | BA4: TOKYO | BB4: ルクア大阪 | BC4: ヒュッテ | BD4: 京王新宿 | BE4: 6142 | BF4: 玉川高島屋 | BG4: NODE | BH4: 大丸心斎橋 | BI4: NARITA
D5: 12100003210L/XL | E5: Varmland Cap | F5: FRV | G5: 0 | H5: 0 | I5: 0 | J5: 0 | K5: 0 | L5: 0 | M5: 0 | N5: 0 | O5: 0 | P5: 0 | Q5: 0 | R5: 0 | S5: 0 | T5: 0 | U5: 0 | AC5: 0 | AD5: 1 | AE5: 0 | AF5: 1 | AG5: 0 | AH5: 1 | AI5: 0 | AJ5: 0 | AK5: 0 | AL5: 0 | AM5: 0 | AN5: 0 | AO5: 0 | AW5: =order!AE4 | AX5: =order!AF4 | AY5: =order!AG4 | AZ5: =order!AH4 | BA5: =order!AI4 | BB5: =order!AJ4 | BC5: =order!AK4 | BD5: =order!AL4 | ... BI5: =order!AQ4 | BQ5: 20260823
D6: 12100003210S/M | E6: Varmland Cap | F6: FRV | G6: 0 | H6: 0 | I6: 0 | J6: 0 | K6: 0 | L6: 0 | M6: 0 | N6: 0 | O6: 0 | P6: 0 | Q6: 0 | R6: 0 | S6: 0 | T6: 0 | U6: 0 | AC6: 0 | AD6: 1 | AE6: 0 | AF6: 1 | AG6: 0 | AH6: 1 | AI6: 1 | AJ6: 0 | AK6: 0 | AL6: 0 | AM6: 0 | AN6: 1 | AO6: 0 | AW6: =order!AE5 | AX6: =order!AF5 | AY6: =order!AG5 | AZ6: =order!AH5 | BA6: =order!AI5 | BB6: =order!AJ5 | BC6: =order!AK5 | BD6: =order!AL5 | ... BI6: =order!AQ5 | BQ6: 20260823
D7: 12100003625L/XL | E7: Varmland Cap | F7: FRV | G7: 0 | H7: 0 | I7: 0 | J7: 0 | K7: 0 | L7: 0 | M7: 0 | N7: 0 | O7: 0 | P7: 0 | Q7: 0 | R7: 0 | S7: 0 | T7: 0 | U7: 0 | AC7: 0 | AD7: 0 | AE7: 0 | AF7: 0 | AG7: 0 | AH7: 2 | AI7: 0 | AJ7: 1 | AK7: 0 | AL7: 0 | AM7: 0 | AN7: 1 | AO7: 0 | AW7: =order!AE6 | AX7: =order!AF6 | AY7: =order!AG6 | AZ7: =order!AH6 | BA7: =order!AI6 | BB7: =order!AJ6 | BC7: =order!AK6 | BD7: =order!AL6 | ... BI7: =order!AQ6 | BQ7: 20260823
D8: 12100003625S/M | E8: Varmland Cap | F8: FRV | G8: 0 | H8: 0 | I8: 0 | J8: 0 | K8: 0 | L8: 0 | M8: 0 | N8: 0 | O8: 0 | P8: 0 | Q8: 0 | R8: 0 | S8: 0 | T8: 0 | U8: 0 | AC8: 0 | AD8: 2 | AE8: 0 | AF8: 0 | AG8: 0 | AH8: 2 | AI8: 2 | AJ8: 2 | AK8: 0 | AL8: 2 | AM8: 0 | AN8: 1 | AO8: 0 | AW8: =order!AE7 | AX8: =order!AF7 | AY8: =order!AG7 | AZ8: =order!AH7 | BA8: =order!AI7 | BB8: =order!AJ7 | BC8: =order!AK7 | BD8: =order!AL7 | ... BI8: =order!AQ7 | BQ8: 20260823
D9: 12100003662L/XL | E9: Varmland Cap | F9: FRV | G9: 0 | H9: 0 | I9: 0 | J9: 0 | K9: 0 | L9: 0 | M9: 0 | N9: 0 | O9: 0 | P9: 0 | Q9: 0 | R9: 0 | S9: 0 | T9: 0 | U9: 0 | AC9: 0 | AD9: 1 | AE9: 0 | AF9: 0 | AG9: 0 | AH9: 0 | AI9: 0 | AJ9: 0 | AK9: 0 | AL9: 0 | AM9: 0 | AN9: 0 | AO9: 0 | AW9: =order!AE8 | AX9: =order!AF8 | AY9: =order!AG8 | AZ9: =order!AH8 | BA9: =order!AI8 | BB9: =order!AJ8 | BC9: =order!AK8 | BD9: =order!AL8 | ... BI9: =order!AQ8 | BQ9: 20260823
D10: 12100003662S/M | E10: Varmland Cap | F10: FRV | G10: 0 | H10: 0 | I10: 0 | J10: 0 | K10: 0 | L10: 0 | M10: 0 | N10: 0 | O10: 0 | P10: 0 | Q10: 0 | R10: 0 | S10: 0 | T10: 0 | U10: 0 | AC10: 0 | AD10: 1 | AE10: 0 | AF10: 1 | AG10: 0 | AH10: 1 | AI10: 2 | AJ10: 1 | AK10: 0 | AL10: 1 | AM10: 0 | AN10: 2 | AO10: 0 | AW10: =order!AE9 | AX10: =order!AF9 | AY10: =order!AG9 | AZ10: =order!AH9 | BA10: =order!AI9 | BB10: =order!AJ9 | BC10: =order!AK9 | BD10: =order!AL9 | ... BI10: =order!AQ9 | BQ10: 20260823
D11: 12100004113L/XL | E11: High Coast Wind Cap | F11: FRV | G11: 0 | H11: 0 | I11: 0 | J11: 0 | K11: 0 | L11: 0 | M11: 0 | N11: 0 | O11: 0 | P11: 0 | Q11: 0 | R11: 0 | S11: 0 | T11: 0 | U11: 0 | AC11: 0 | AD11: 0 | AE11: 0 | AF11: 0 | AG11: 1 | AH11: 0 | AI11: 0 | AJ11: 1 | AK11: 0 | AL11: 0 | AM11: 0 | AN11: 0 | AO11: 0 | AW11: =order!AE10 | AX11: =order!AF10 | AY11: =order!AG10 | AZ11: =order!AH10 | BA11: =order!AI10 | BB11: =order!AJ10 | BC11: =order!AK10 | BD11: =order!AL10 | ... BI11: =order!AQ10 | BQ11: 20260823
D12: 12100004300L/XL | E12: High Coast Wind Cap | F12: FRV | G12: 0 | H12: 0 | I12: 0 | J12: 0 | K12: 0 | L12: 0 | M12: 0 | N12: 0 | O12: 0 | P12: 0 | Q12: 0 | R12: 0 | S12: 0 | T12: 0 | U12: 0 | AC12: 0 | AD12: 1 | AE12: 0 | AF12: 0 | AG12: 0 | AH12: 0 | AI12: 0 | AJ12: 0 | AK12: 0 | AL12: 0 | AM12: 0 | AN12: 0 | AO12: 0 | AW12: =order!AE11 | AX12: =order!AF11 | AY12: =order!AG11 | AZ12: =order!AH11 | BA12: =order!AI11 | BB12: =order!AJ11 | BC12: =order!AK11 | BD12: =order!AL11 | ... BI12: =order!AQ11 | BQ12: 20260823
D13: 12100004300S/M | E13: High Coast Wind Cap | F13: FRV | G13: 1 | H13: 0 | I13: 0 | J13: 0 | K13: 0 | L13: 0 | M13: 0 | N13: 0 | O13: 0 | P13: 0 | Q13: 0 | R13: 0 | S13: 0 | T13: 0 | U13: 0 | AC13: 0 | AD13: 1 | AE13: 0 | AF13: 2 | AG13: 0 | AH13: 1 | AI13: 0 | AJ13: 0 | AK13: 0 | AL13: 0 | AM13: 0 | AN13: 1 | AO13: 0 | AW13: =order!AE12 | AX13: =order!AF12 | AY13: =order!AG12 | AZ13: =order!AH12 | BA13: =order!AI12 | BB13: =order!AJ12 | BC13: =order!AK12 | BD13: =order!AL12 | ... BI13: =order!AQ12 | BQ13: 20260823
D14: 12100004550L/XL | E14: High Coast Wind Cap | F14: FRV | G14: 0 | H14: 0 | I14: 0 | J14: 0 | K14: 0 | L14: 0 | M14: 0 | N14: 0 | O14: 0 | P14: 0 | Q14: 0 | R14: 0 | S14: 0 | T14: 0 | U14: 0 | AC14: 0 | AD14: 1 | AE14: 0 | AF14: 0 | AG14: 0 | AH14: 0 | AI14: 0 | AJ14: 1 | AK14: 0 | AL14: 0 | AM14: 0 | AN14: 0 | AO14: 0 | AW14: =order!AE13 | AX14: =order!AF13 | AY14: =order!AG13 | AZ14: =order!AH13 | BA14: =order!AI13 | BB14: =order!AJ13 | BC14: =order!AK13 | BD14: =order!AL13 | ... BI14: =order!AQ13 | BQ14: 20260823
D15: 12100004550S/M | E15: High Coast Wind Cap | F15: FRV | G15: 0 | H15: 0 | I15: 0 | J15: 0 | K15: 0 | L15: 0 | M15: 0 | N15: 0 | O15: 0 | P15: 0 | Q15: 0 | R15: 0 | S15: 0 | T15: 0 | U15: 0 | AC15: 0 | AD15: 0 | AE15: 0 | AF15: 0 | AG15: 0 | AH15: 0 | AI15: 1 | AJ15: 2 | AK15: 0 | AL15: 0 | AM15: 0 | AN15: 0 | AO15: 0 | AW15: =order!AE14 | AX15: =order!AF14 | AY15: =order!AG14 | AZ15: =order!AH14 | BA15: =order!AI14 | BB15: =order!AJ14 | BC15: =order!AK14 | BD15: =order!AL14 | ... BI15: =order!AQ14 | BQ15: 20260823
D16: 12100004555S/M | E16: High Coast Wind Cap | F16: FRV | G16: 1 | H16: 0 | I16: 0 | J16: 0 | K16: 0 | L16: 0 | M16: 0 | N16: 0 | O16: 0 | P16: 0 | Q16: 0 | R16: 0 | S16: 0 | T16: 0 | U16: 0 | AC16: 0 | AD16: 0 | AE16: 0 | AF16: 0 | AG16: 0 | AH16: 0 | AI16: 0 | AJ16: 0 | AK16: 0 | AL16: 0 | AM16: 0 | AN16: 0 | AO16: 0 | AW16: =order!AE15 | AX16: =order!AF15 | AY16: =order!AG15 | AZ16: =order!AH15 | BA16: =order!AI15 | BB16: =order!AJ15 | BC16: =order!AK15 | BD16: =order!AL15 | ... BI16: =order!AQ15 | BQ16: 20260823
... D29: 12200190550XS | E29: Bergtagen GTX Pro Trousers M | F29: FRV | G29: 0 | H29: 0 | I29: 0 | J29: 0 | K29: 0 | L29: 0 | M29: 0 | N29: 0 | O29: 0 | P29: 0 | Q29: 0 | R29: 0 | S29: 0 | T29: 0 | U29: 0 | AC29: 0 | AD29: 0 | AE29: 0 | AF29: 1 | AG29: 0 | AH29: 0 | AI29: 1 | AJ29: 0 | AK29: 0 | AL29: 0 | AM29: 0 | AN29: 0 | AO29: 0 | AW29: =order!AE28 | AX29: =order!AF28 | AY29: =order!AG28 | AZ29: =order!AH28 | BA29: =order!AI28 | BB29: =order!AJ28 | BC29: =order!AK28 | BD29: =order!AL28 | ... BI29: =order!AQ28 | BQ29: 20260823
D30: 1220019755044 | E30: Hoja Hybrid Trousers M | F30: FRV | G30: 0 | H30: 5 | I30: 0 | J30: 0 | K30: 0 | L30: 0 | M30: 0 | N30: 0 | O30: 0 | P30: 0 | Q30: 0 | R30: 0 | S30: 0 | T30: 0 | U30: 0 | AC30: 0 | AD30: 1 | AE30: 0 | AF30: 1 | AG30: 1 | AH30: 1 | AI30: 0 | AJ30: 1 | AK30: 0 | AL30: 1 | AM30: 0 | AN30: 1 | AO30: 0 | AW30: =order!AE29 | AX30: =order!AF29 | AY30: =order!AG29 | AZ30: =order!AH29 | BA30: =order!AI29 | BB30: =order!AJ29 | BC30: =order!AK29 | BD30: =order!AL29 | ... BI30: =order!AQ29 | BQ30: 20260823
D31: 1220019755046 | E31: Hoja Hybrid Trousers M | F31: FRV | G31: 1 | H31: 10 | I31: 0 | J31: 0 | K31: 0 | L31: 0 | M31: 0 | N31: 0 | O31: 0 | P31: 0 | Q31: 0 | R31: 0 | S31: 0 | T31: 0 | U31: 0 | AC31: 0 | AD31: 1 | AE31: 0 | AF31: 2 | AG31: 1 | AH31: 1 | AI31: 1 | AJ31: 1 | AK31: 0 | AL31: 1 | AM31: 0 | AN31: 1 | AO31: 0 | AW31: =order!AE30 | AX31: =order!AF30 | AY31: =order!AG30 | AZ31: =order!AH30 | BA31: =order!AI30 | BB31: =order!AJ30 | BC31: =order!AK30 | BD31: =order!AL30 | ... BI31: =order!AQ30 | BQ31: 20260823
D32: 1220019755048 | E32: Hoja Hybrid Trousers M | F32: FRV | G32: 0 | H32: 7 | I32: 0 | J32: 0 | K32: 0 | L32: 0 | M32: 0 | N32: 0 | O32: 0 | P32: 0 | Q32: 0 | R32: 0 | S32: 0 | T32: 0 | U32: 0 | AC32: 0 | AD32: 1 | AE32: 0 | AF32: 1 | AG32: 0 | AH32: 1 | AI32: 1 | AJ32: 1 | AK32: 0 | AL32: 1 | AM32: 0 | AN32: 1 | AO32: 0 | AW32: =order!AE31 | AX32: =order!AF31 | AY32: =order!AG31 | AZ32: =order!AH31 | BA32: =order!AI31 | BB32: =order!AJ31 | BC32: =order!AK31 | BD32: =order!AL31 | ... BI32: =order!AQ31 | BQ32: 20260823
D33: 1220019755050 | E33: Hoja Hybrid Trousers M | F33: FRV | G33: 0 | H33: 3 | I33: 0 | J33: 0 | K33: 0 | L33: 0 | M33: 0 | N33: 0 | O33: 0 | P33: 0 | Q33: 0 | R33: 0 | S33: 0 | T33: 0 | U33: 0 | AC33: 0 | AD33: 1 | AE33: 0 | AF33: 1 | AG33: 1 | AH33: 1 | AI33: 1 | AJ33: 1 | AK33: 0 | AL33: 1 | AM33: 0 | AN33: 1 | AO33: 0 | AW33: =order!AE32 | AX33: =order!AF32 | AY33: =order!AG32 | AZ33: =order!AH32 | BA33: =order!AI32 | BB33: =order!AJ32 | BC33: =order!AK32 | BD33: =order!AL32 | ... BI33: =order!AQ32 | BQ33: 20260823
D34: 1220019755052 | E34: Hoja Hybrid Trousers M | F34: FRV | G34: 0 | H34: 0 | I34: 0 | J34: 0 | K34: 0 | L34: 0 | M34: 0 | N34: 0 | O34: 0 | P34: 0 | Q34: 0 | R34: 0 | S34: 0 | T34: 0 | U34: 0 | AC34: 0 | AD34: 0 | AE34: 0 | AF34: 1 | AG34: 1 | AH34: 0 | AI34: 0 | AJ34: 0 | AK34: 0 | AL34: 0 | AM34: 0 | AN34: 0 | AO34: 0 | AW34: =order!AE33 | AX34: =order!AF33 | AY34: =order!AG33 | AZ34: =order!AH33 | BA34: =order!AI33 | BB34: =order!AJ33 | BC34: =order!AK33 | BD34: =order!AL33 | ... BI34: =order!AQ33 | BQ34: 20260823
D35: 1220020755046 | E35: High Coast Pack Shorts M | F35: FRV | G35: 1 | H35: 0 | I35: 0 | J35: 0 | K35: 0 | L35: 0 | M35: 0 | N35: 0 | O35: 0 | P35: 0 | Q35: 0 | R35: 0 | S35: 0 | T35: 0 | U35: 0 | AC35: 0 | AD35: 1 | AE35: 0 | AF35: 1 | AG35: 1 | AH35: 1 | AI35: 0 | AJ35: 1 | AK35: 0 | AL35: 1 | AM35: 1 | AN35: 1 | AO35: 0 | AW35: =order!AE34 | AX35: =order!AF34 | AY35: =order!AG34 | AZ35: =order!AH34 | BA35: =order!AI34 | BB35: =order!AJ34 | BC35: =order!AK34 | BD35: =order!AL34 | ... BI35: =order!AQ34 | BQ35: 20260823
D36: 1220020755048 | E36: High Coast Pack Shorts M | F36: FRV | G36: 1 | H36: 0 | I36: 0 | J36: 0 | K36: 0 | L36: 0 | M36: 0 | N36: 0 | O36: 0 | P36: 0 | Q36: 0 | R36: 0 | S36: 0 | T36: 0 | U36: 0 | AC36: 0 | AD36: 1 | AE36: 0 | AF36: 1 | AG36: 1 | AH36: 1 | AI36: 1 | AJ36: 1 | AK36: 0 | AL36: 1 | AM36: 1 | AN36: 1 | AO36: 0 | AW36: =order!AE35 | AX36: =order!AF35 | AY36: =order!AG35 | AZ36: =order!AH35 | BA36: =order!AI35 | BB36: =order!AJ35 | BC36: =order!AK35 | BD36: =order!AL35 | ... BI36: =order!AQ35 | BQ36: 20260823
D37: 1220020755050 | E37: High Coast Pack Shorts M | F37: FRV | G37: 0 | H37: 0 | I37: 0 | J37: 0 | K37: 0 | L37: 0 | M37: 0 | N37: 0 | O37: 0 | P37: 0 | Q37: 0 | R37: 0 | S37: 0 | T37: 0 | U37: 0 | AC37: 0 | AD37: 1 | AE37: 0 | AF37: 1 | AG37: 1 | AH37: 1 | AI37: 1 | AJ37: 1 | AK37: 0 | AL37: 1 | AM37: 1 | AN37: 1 | AO37: 0 | AW37: =order!AE36 | AX37: =order!AF36 | AY37: =order!AG36 | AZ37: =order!AH36 | BA37: =order!AI36 | BB37: =order!AJ36 | BC37: =order!AK36 | BD37: =order!AL36 | ... BI37: =order!AQ36 | BQ37: 20260823
D38: 1220020755052 | E38: High Coast Pack Shorts M | F38: FRV | G38: 0 | H38: 0 | I38: 0 | J38: 0 | K38: 0 | L38: 0 | M38: 0 | N38: 0 | O38: 0 | P38: 0 | Q38: 0 | R38: 0 | S38: 0 | T38: 0 | U38: 0 | AC38: 0 | AD38: 1 | AE38: 0 | AF38: 1 | AG38: 0 | AH38: 1 | AI38: 0 | AJ38: 0 | AK38: 0 | AL38: 0 | AM38: 0 | AN38: 0 | AO38: 0 | AW38: =order!AE37 | AX38: =order!AF37 | AY38: =order!AG37 | AZ38: =order!AH37 | BA38: =order!AI37 | BB38: =order!AJ37 | BC38: =order!AK37 | BD38: =order!AL37 | ... BI38: =order!AQ37 | BQ38: 20260823
D39: 1220020762546 | E39: High Coast Pack Shorts M | F39: FRV | G39: 4 | H39: 0 | I39: 0 | J39: 0 | K39: 0 | L39: 0 | M39: 0 | N39: 0 | O39: 0 | P39: 0 | Q39: 0 | R39: 0 | S39: 0 | T39: 0 | U39: 0 | AC39: 0 | AD39: 1 | AE39: 0 | AF39: 1 | AG39: 1 | AH39: 1 | AI39: 1 | AJ39: 1 | AK39: 0 | AL39: 1 | AM39: 1 | AN39: 1 | AO39: 0 | AW39: =order!AE38 | AX39: =order!AF38 | AY39: =order!AG38 | AZ39: =order!AH38 | BA39: =order!AI38 | BB39: =order!AJ38 | BC39: =order!AK38 | BD39: =order!AL38 | ... BI39: =order!AQ38 | BQ39: 20260823
D40: 1220020762548 | E40: High Coast Pack Shorts M | F40: FRV | G40: 0 | H40: 0 | I40: 0 | J40: 0 | K40: 0 | L40: 0 | M40: 0 | N40: 0 | O40: 0 | P40: 0 | Q40: 0 | R40: 0 | S40: 0 | T40: 0 | U40: 0 | AC40: 0 | AD40: 1 | AE40: 0 | AF40: 1 | AG40: 1 | AH40: 0 | AI40: 1 | AJ40: 1 | AK40: 0 | AL40: 1 | AM40: 1 | AN40: 1 | AO40: 0 | AW40: =order!AE39 | AX40: =order!AF39 | AY40: =order!AG39 | AZ40: =order!AH39 | BA40: =order!AI39 | BB40: =order!AJ39 | BC40: =order!AK39 | BD40: =order!AL39 | ... BI40: =order!AQ39 | BQ40: 20260823
D41: 1220020762550 | E41: High Coast Pack Shorts M | F41: FRV | G41: 2 | H41: 0 | I41: 0 | J41: 0 | K41: 0 | L41: 0 | M41: 0 | N41: 0 | O41: 0 | P41: 0 | Q41: 0 | R41: 0 | S41: 0 | T41: 0 | U41: 0 | AC41: 0 | AD41: 1 | AE41: 0 | AF41: 1 | AG41: 0 | AH41: 1 | AI41: 1 | AJ41: 1 | AK41: 0 | AL41: 1 | AM41: 1 | AN41: 1 | AO41: 0 | AW41: =order!AE40 | AX41: =order!AF40 | AY41: =order!AG40 | AZ41: =order!AH40 | BA41: =order!AI40 | BB41: =order!AJ40 | BC41: =order!AK40 | BD41: =order!AL40 | ... BI41: =order!AQ40 | BQ41: 20260823
D42: 12200218550L | E42: Keb GTX Trousers M | F42: FRV | G42: 0 | H42: 0 | I42: 0 | J42: 0 | K42: 0 | L42: 0 | M42: 0 | N42: 0 | O42: 0 | P42: 0 | Q42: 0 | R42: 0 | S42: 0 | T42: 0 | U42: 0 | AC42: 0 | AD42: 1 | AE42: 0 | AF42: 0 | AG42: 1 | AH42: 0 | AI42: 0 | AJ42: 0 | AK42: 0 | AL42: 0 | AM42: 1 | AN42: 0 | AO42: 0 | AW42: =order!AE41 | AX42: =order!AF41 | AY42: =order!AG41 | AZ42: =order!AH41 | BA42: =order!AI41 | BB42: =order!AJ41 | BC42: =order!AK41 | BD42: =order!AL41 | ... BI42: =order!AQ41 | BQ42: 20260823
D43: 12200218550M | E43: Keb GTX Trousers M | F43: FRV | G43: 0 | H43: 0 | I43: 0 | J43: 0 | K43: 0 | L43: 0 | M43: 0 | N43: 0 | O43: 0 | P43: 0 | Q43: 0 | R43: 0 | S43: 0 | T43: 0 | U43: 0 | AC43: 0 | AD43: 1 | AE43: 0 | AF43: 1 | AG43: 0 | AH43: 0 | AI43: 1 | AJ43: 1 | AK43: 0 | AL43: 0 | AM43: 1 | AN43: 1 | AO43: 0 | AW43: =order!AE42 | AX43: =order!AF42 | AY43: =order!AG42 | AZ43: =order!AH42 | BA43: =order!AI42 | BB43: =order!AJ42 | BC43: =order!AK42 | BD43: =order!AL42 | ... BI43: =order!AQ42 | BQ43: 20260823
D44: 12200218550S | E44: Keb GTX Trousers M | F44: FRV | G44: 0 | H44: 0 | I44: 0 | J44: 0 | K44: 0 | L44: 0 | M44: 0 | N44: 0 | O44: 0 | P44: 0 | Q44: 0 | R44: 0 | S44: 0 | T44: 0 | U44: 0 | AC44: 0 | AD44: 1 | AE44: 0 | AF44: 0 | AG44: 0 | AH44: 1 | AI44: 0 | AJ44: 1 | AK44: 0 | AL44: 1 | AM44: 0 | AN44: 0 | AO44: 0 | AW44: =order!AE43 | AX44: =order!AF43 | AY44: =order!AG43 | AZ44: =order!AH43 | BA44: =order!AI43 | BB44: =order!AJ43 | BC44: =order!AK43 | BD44: =order!AL43 | ... BI44: =order!AQ43 | BQ44: 20260823
D45: 12200218550XS | E45: Keb GTX Trousers M | F45: FRV | G45: 0 | H45: 0 | I45: 0 | J45: 0 | K45: 0 | L45: 0 | M45: 0 | N45: 0 | O45: 0 | P45: 0 | Q45: 0 | R45: 0 | S45: 0 | T45: 0 | U45: 0 | AC45: 0 | AD45: 1 | AE45: 0 | AF45: 1 | AG45: 1 | AH45: 1 | AI45: 1 | AJ45: 0 | AK45: 0 | AL45: 0 | AM45: 0 | AN45: 0 | AO45: 0 | AW45: =order!AE44 | AX45: =order!AF44 | AY45: =order!AG44 | AZ45: =order!AH44 | BA45: =order!AI44 | BB45: =order!AJ44 | BC45: =order!AK44 | BD45: =order!AL44 | ... BI45: =order!AQ44 | BQ45: 20260823
D46: 12200219537M | E46: Vardag Summer Shorts M | F46: FRV | G46: 0 | H46: 0 | I46: 0 | J46: 0 | K46: 0 | L46: 0 | M46: 0 | N46: 0 | O46: 0 | P46: 0 | Q46: 0 | R46: 0 | S46: 0 | T46: 0 | U46: 0 | AC46: 0 | AD46: 0 | AE46: 0 | AF46: 1 | AG46: 1 | AH46: 0 | AI46: 0 | AJ46: 0 | AK46: 0 | AL46: 0 | AM46: 0 | AN46: 0 | AO46: 0 | AW46: =order!AE45 | AX46: =order!AF45 | AY46: =order!AG45 | AZ46: =order!AH45 | BA46: =order!AI45 | BB46: =order!AJ45 | BC46: =order!AK45 | BD46: =order!AL45 | ... BI46: =order!AQ45 | BQ46: 20260823
D47: 12200219537S | E47: Vardag Summer Shorts M | F47: FRV | G47: 2 | H47: 0 | I47: 0 | J47: 0 | K47: 0 | L47: 0 | M47: 0 | N47: 0 | O47: 0 | P47: 0 | Q47: 0 | R47: 0 | S47: 0 | T47: 0 | U47: 0 | AC47: 0 | AD47: 1 | AE47: 0 | AF47: 1 | AG47: 1 | AH47: 1 | AI47: 0 | AJ47: 0 | AK47: 0 | AL47: 0 | AM47: 1 | AN47: 0 | AO47: 0 | AW47: =order!AE46 | AX47: =order!AF46 | AY47: =order!AG46 | AZ47: =order!AH46 | BA47: =order!AI46 | BB47: =order!AJ46 | BC47: =order!AK46 | BD47: =order!AL46 | ... BI47: =order!AQ46 | BQ47: 20260823
D48: 12200219550L | E48: Vardag Summer Shorts M | F48: FRV | G48: 0 | H48: 0 | I48: 0 | J48: 0 | K48: 0 | L48: 0 | M48: 0 | N48: 0 | O48: 0 | P48: 0 | Q48: 0 | R48: 0 | S48: 0 | T48: 0 | U48: 0 | AC48: 0 | AD48: 1 | AE48: 0 | AF48: 1 | AG48: 1 | AH48: 1 | AI48: 0 | AJ48: 0 | AK48: 0 | AL48: 0 | AM48: 0 | AN48: 0 | AO48: 0 | AW48: =order!AE47 | AX48: =order!AF47 | AY48: =order!AG47 | AZ48: =order!AH47 | BA48: =order!AI47 | BB48: =order!AJ47 | BC48: =order!AK47 | BD48: =order!AL47 | ... BI48: =order!AQ47 | BQ48: 20260823
D49: 12200219550M | E49: Vardag Summer Shorts M | F49: FRV | G49: 5 | H49: 0 | I49: 0 | J49: 0 | K49: 0 | L49: 0 | M49: 0 | N49: 0 | O49: 0 | P49: 0 | Q49: 0 | R49: 0 | S49: 0 | T49: 0 | U49: 0 | AC49: 0 | AD49: 1 | AE49: 0 | AF49: 0 | AG49: 1 | AH49: 1 | AI49: 0 | AJ49: 0 | AK49: 0 | AL49: 0 | AM49: 1 | AN49: 1 | AO49: 0 | AW49: =order!AE48 | AX49: =order!AF48 | AY49: =order!AG48 | AZ49: =order!AH48 | BA49: =order!AI48 | BB49: =order!AJ48 | BC49: =order!AK48 | BD49: =order!AL48 | ... BI49: =order!AQ48 | BQ49: 20260823
D50: 12200219550S | E50: Vardag Summer Shorts M | F50: FRV | G50: 0 | H50: 0 | I50: 0 | J50: 0 | K50: 0 | L50: 0 | M50: 0 | N50: 0 | O50: 0 | P50: 0 | Q50: 0 | R50: 0 | S50: 0 | T50: 0 | U50: 0 | AC50: 0 | AD50: 1 | AE50: 0 | AF50: 1 | AG50: 1 | AH50: 1 | AI50: 0 | AJ50: 0 | AK50: 0 | AL50: 0 | AM50: 2 | AN50: 1 | AO50: 0 | AW50: =order!AE49 | AX50: =order!AF49 | AY50: =order!AG49 | AZ50: =order!AH49 | BA50: =order!AI49 | BB50: =order!AJ49 | BC50: =order!AK49 | BD50: =order!AL49 | ... BI50: =order!AQ49 | BQ50: 20260823
D51: 12200219625L | E51: Vardag Summer Shorts M | F51: FRV | G51: 0 | H51: 0 | I51: 0 | J51: 0 | K51: 0 | L51: 0 | M51: 0 | N51: 0 | O51: 0 | P51: 0 | Q51: 0 | R51: 0 | S51: 0 | T51: 0 | U51: 0 | AC51: 0 | AD51: 0 | AE51: 0 | AF51: 1 | AG51: 0 | AH51: 0 | AI51: 0 | AJ51: 0 | AK51: 0 | AL51: 0 | AM51: 0 | AN51: 0 | AO51: 0 | AW51: =order!AE50 | AX51: =order!AF50 | AY51: =order!AG50 | AZ51: =order!AH50 | BA51: =order!AI50 | BB51: =order!AJ50 | BC51: =order!AK50 | BD51: =order!AL50 | ... BI51: =order!AQ50 | BQ51: 20260823
D52: 12200219625M | E52: Vardag Summer Shorts M | F52: FRV | G52: 0 | H52: 0 | I52: 0 | J52: 0 | K52: 0 | L52: 0 | M52: 0 | N52: 0 | O52: 0 | P52: 0 | Q52: 0 | R52: 0 | S52: 0 | T52: 0 | U52: 0 | AC52: 0 | AD52: 1 | AE52: 0 | AF52: 0 | AG52: 0 | AH52: 0 | AI52: 0 | AJ52: 0 | AK52: 0 | AL52: 0 | AM52: 1 | AN52: 1 | AO52: 0 | AW52: =order!AE51 | AX52: =order!AF51 | AY52: =order!AG51 | AZ52: =order!AH51 | BA52: =order!AI51 | BB52: =order!AJ51 | BC52: =order!AK51 | BD52: =order!AL51 | ... BI52: =order!AQ51 | BQ52: 20260823
...

Sheet order
C1: =SUBTOTAL(9,C4:C3500) | D1: =SUBTOTAL(9,D4:D3500) | E1: =SUBTOTAL(9,E4:E3500) | F1: =SUBTOTAL(9,F4:F3500) | G1: =SUBTOTAL(9,G4:G3500) | H1: =SUBTOTAL(9,H4:H3500) | I1: =SUBTOTAL(9,I4:I3500) | J1: =SUBTOTAL(9,J4:J3500) | ... AQ1: =SUBTOTAL(9,AQ4:AQ3500)
C2: 確保 | R2: 在庫 | AE2: ORDER | AR2: 過不足
A3: 商品コード | B3: 商品名 | C3: NWA | D3: RETAIL確保 | E3: ZOZO | F3: 名古屋 | G3: 丸井web | H3: YSEC | I3: TOKYO | J3: ルクア大阪 | K3: ヒュッテ | L3: 京王新宿 | M3: 6142 | N3: 玉川高島屋 | O3: NODE | P3: 大丸心斎橋 | Q3: NARITA | R3: ZOZO | S3: 名古屋 | T3: 丸井web | U3: YSEC | V3: TOKYO | W3: ルクア大阪 | X3: ヒュッテ | Y3: 京王新宿 | Z3: 6142 | AA3: 玉川高島屋 | AB3: NODE | AC3: 大丸心斎橋 | AD3: NARITA | AE3: ZOZO | AF3: 名古屋 | AG3: 丸井web | AH3: YSEC | AI3: TOKYO | AJ3: ルクア大阪 | AK3: ヒュッテ | AL3: 京王新宿 | AM3: 6142 | AN3: 玉川高島屋 | AO3: NODE | AP3: 大丸心斎橋 | AQ3: NARITA | AR3: ZOZO | AS3: 名古屋 | AT3: 丸井web | AU3: YSEC | AV3: TOKYO | AW3: ルクア大阪 | AX3: ヒュッテ | AY3: 京王新宿 | AZ3: 6142 | BA3: 玉川高島屋 | BB3: NODE | BC3: 大丸心斎橋 | BD3: NARITA | BG3: 過不足 | BH3: 希望品 | BI3: HUTTE | BJ3: ZOZO | BK3: OIOI | BL3: R | BM3: 特価
A4: 12100003210L/XL | B4: Varmland Cap | E4: 0 | F4: 0 | G4: 0 | H4: 0 | I4: 0 | J4: 0 | K4: 0 | L4: 0 | M4: 0 | N4: 0 | O4: 0 | P4: 0 | Q4: 0 | S4: 1 | U4: 1 | W4: 1 | AR4: =E4-AE4 | AS4: =F4-AF4 | AT4: =G4-AG4 | AU4: =H4-AH4 | AV4: =I4-AI4 | AW4: =J4-AJ4 | AX4: =K4-AK4 | AY4: =L4-AL4 | ... BD4: =Q4-AQ4 | BE4: =SUMIF(AR4:BD4,"<0",AR4:BD4) | BF4: =IF(BE4<0,D4+BE4,D4) | BG4: =IF(IF(BF4<0,C4+BF4,C4)=0,"",IF(BF4<0,C4+BF4,C4)) | BJ4: 0 | BK4: 0 | BL4: 1
A5: 12100003210S/M | B5: Varmland Cap | E5: 0 | F5: 0 | G5: 0 | H5: 0 | I5: 0 | J5: 0 | K5: 0 | L5: 0 | M5: 0 | N5: 0 | O5: 0 | P5: 0 | Q5: 0 | S5: 1 | U5: 1 | W5: 1 | X5: 1 | AC5: 1 | AR5: =E5-AE5 | AS5: =F5-AF5 | AT5: =G5-AG5 | AU5: =H5-AH5 | AV5: =I5-AI5 | AW5: =J5-AJ5 | AX5: =K5-AK5 | AY5: =L5-AL5 | ... BD5: =Q5-AQ5 | BE5: =SUMIF(AR5:BD5,"<0",AR5:BD5) | BF5: =IF(BE5<0,D5+BE5,D5) | BG5: =IF(IF(BF5<0,C5+BF5,C5)=0,"",IF(BF5<0,C5+BF5,C5)) | BJ5: 0 | BK5: 0 | BL5: 2
A6: 12100003625L/XL | B6: Varmland Cap | E6: 0 | F6: 0 | G6: 0 | H6: 0 | I6: 0 | J6: 0 | K6: 0 | L6: 0 | M6: 0 | N6: 0 | O6: 0 | P6: 0 | Q6: 0 | W6: 2 | Y6: 1 | AC6: 1 | AR6: =E6-AE6 | AS6: =F6-AF6 | AT6: =G6-AG6 | AU6: =H6-AH6 | AV6: =I6-AI6 | AW6: =J6-AJ6 | AX6: =K6-AK6 | AY6: =L6-AL6 | ... BD6: =Q6-AQ6 | BE6: =SUMIF(AR6:BD6,"<0",AR6:BD6) | BF6: =IF(BE6<0,D6+BE6,D6) | BG6: =IF(IF(BF6<0,C6+BF6,C6)=0,"",IF(BF6<0,C6+BF6,C6)) | BJ6: 0 | BK6: 0 | BL6: 3
A7: 12100003625S/M | B7: Varmland Cap | E7: 0 | F7: 0 | G7: 0 | H7: 0 | I7: 0 | J7: 0 | K7: 0 | L7: 0 | M7: 0 | N7: 0 | O7: 0 | P7: 0 | Q7: 0 | S7: 2 | W7: 2 | X7: 2 | Y7: 2 | AA7: 2 | AC7: 1 | AR7: =E7-AE7 | AS7: =F7-AF7 | AT7: =G7-AG7 | AU7: =H7-AH7 | AV7: =I7-AI7 | AW7: =J7-AJ7 | AX7: =K7-AK7 | AY7: =L7-AL7 | ... BD7: =Q7-AQ7 | BE7: =SUMIF(AR7:BD7,"<0",AR7:BD7) | BF7: =IF(BE7<0,D7+BE7,D7) | BG7: =IF(IF(BF7<0,C7+BF7,C7)=0,"",IF(BF7<0,C7+BF7,C7)) | BJ7: 0 | BK7: 0 | BL7: 4
A8: 12100003662L/XL | B8: Varmland Cap | E8: 0 | F8: 0 | G8: 0 | H8: 0 | I8: 0 | J8: 0 | K8: 0 | L8: 0 | M8: 0 | N8: 0 | O8: 0 | P8: 0 | Q8: 0 | S8: 1 | AR8: =E8-AE8 | AS8: =F8-AF8 | AT8: =G8-AG8 | AU8: =H8-AH8 | AV8: =I8-AI8 | AW8: =J8-AJ8 | AX8: =K8-AK8 | AY8: =L8-AL8 | ... BD8: =Q8-AQ8 | BE8: =SUMIF(AR8:BD8,"<0",AR8:BD8) | BF8: =IF(BE8<0,D8+BE8,D8) | BG8: =IF(IF(BF8<0,C8+BF8,C8)=0,"",IF(BF8<0,C8+BF8,C8)) | BJ8: 0 | BK8: 0 | BL8: 5
A9: 12100003662S/M | B9: Varmland Cap | E9: 0 | F9: 0 | G9: 0 | H9: 0 | I9: 0 | J9: 0 | K9: 0 | L9: 0 | M9: 0 | N9: 0 | O9: 0 | P9: 0 | Q9: 0 | S9: 1 | U9: 1 | W9: 1 | X9: 2 | Y9: 1 | AA9: 1 | AC9: 2 | AR9: =E9-AE9 | AS9: =F9-AF9 | AT9: =G9-AG9 | AU9: =H9-AH9 | AV9: =I9-AI9 | AW9: =J9-AJ9 | AX9: =K9-AK9 | AY9: =L9-AL9 | ... BD9: =Q9-AQ9 | BE9: =SUMIF(AR9:BD9,"<0",AR9:BD9) | BF9: =IF(BE9<0,D9+BE9,D9) | BG9: =IF(IF(BF9<0,C9+BF9,C9)=0,"",IF(BF9<0,C9+BF9,C9)) | BJ9: 0 | BK9: 0 | BL9: 6
A10: 12100004113L/XL | B10: High Coast Wind Cap | E10: 0 | F10: 0 | G10: 0 | H10: 0 | I10: 0 | J10: 0 | K10: 0 | L10: 0 | M10: 0 | N10: 0 | O10: 0 | P10: 0 | Q10: 0 | V10: 1 | Y10: 1 | AR10: =E10-AE10 | AS10: =F10-AF10 | AT10: =G10-AG10 | AU10: =H10-AH10 | AV10: =I10-AI10 | AW10: =J10-AJ10 | AX10: =K10-AK10 | AY10: =L10-AL10 | ... BD10: =Q10-AQ10 | BE10: =SUMIF(AR10:BD10,"<0",AR10:BD10) | BF10: =IF(BE10<0,D10+BE10,D10) | BG10: =IF(IF(BF10<0,C10+BF10,C10)=0,"",IF(BF10<0,C10+BF10,C10)) | BJ10: 0 | BK10: 0 | BL10: 7
A11: 12100004300L/XL | B11: High Coast Wind Cap | E11: 0 | F11: 0 | G11: 0 | H11: 0 | I11: 0 | J11: 0 | K11: 0 | L11: 0 | M11: 0 | N11: 0 | O11: 0 | P11: 0 | Q11: 0 | S11: 1 | AR11: =E11-AE11 | AS11: =F11-AF11 | AT11: =G11-AG11 | AU11: =H11-AH11 | AV11: =I11-AI11 | AW11: =J11-AJ11 | AX11: =K11-AK11 | AY11: =L11-AL11 | ... BD11: =Q11-AQ11 | BE11: =SUMIF(AR11:BD11,"<0",AR11:BD11) | BF11: =IF(BE11<0,D11+BE11,D11) | BG11: =IF(IF(BF11<0,C11+BF11,C11)=0,"",IF(BF11<0,C11+BF11,C11)) | BJ11: 0 | BK11: 0 | BL11: 8
A12: 12100004300S/M | B12: High Coast Wind Cap | C12: 1 | E12: 0 | F12: 0 | G12: 0 | H12: 0 | I12: 0 | J12: 0 | K12: 0 | L12: 0 | M12: 0 | N12: 0 | O12: 0 | P12: 0 | Q12: 0 | S12: 1 | U12: 2 | W12: 1 | AC12: 1 | AR12: =E12-AE12 | AS12: =F12-AF12 | AT12: =G12-AG12 | AU12: =H12-AH12 | AV12: =I12-AI12 | AW12: =J12-AJ12 | AX12: =K12-AK12 | AY12: =L12-AL12 | ... BD12: =Q12-AQ12 | BE12: =SUMIF(AR12:BD12,"<0",AR12:BD12) | BF12: =IF(BE12<0,D12+BE12,D12) | BG12: =IF(IF(BF12<0,C12+BF12,C12)=0,"",IF(BF12<0,C12+BF12,C12)) | BJ12: 0 | BK12: 0 | BL12: 9
A13: 12100004550L/XL | B13: High Coast Wind Cap | E13: 0 | F13: 0 | G13: 0 | H13: 0 | I13: 0 | J13: 0 | K13: 0 | L13: 0 | M13: 0 | N13: 0 | O13: 0 | P13: 0 | Q13: 0 | S13: 1 | Y13: 1 | AR13: =E13-AE13 | AS13: =F13-AF13 | AT13: =G13-AG13 | AU13: =H13-AH13 | AV13: =I13-AI13 | AW13: =J13-AJ13 | AX13: =K13-AK13 | AY13: =L13-AL13 | ... BD13: =Q13-AQ13 | BE13: =SUMIF(AR13:BD13,"<0",AR13:BD13) | BF13: =IF(BE13<0,D13+BE13,D13) | BG13: =IF(IF(BF13<0,C13+BF13,C13)=0,"",IF(BF13<0,C13+BF13,C13)) | BJ13: 0 | BK13: 0 | BL13: 10
A14: 12100004550S/M | B14: High Coast Wind Cap | E14: 0 | F14: 0 | G14: 0 | H14: 0 | I14: 0 | J14: 0 | K14: 0 | L14: 0 | M14: 0 | N14: 0 | O14: 0 | P14: 0 | Q14: 0 | X14: 1 | Y14: 2 | AR14: =E14-AE14 | AS14: =F14-AF14 | AT14: =G14-AG14 | AU14: =H14-AH14 | AV14: =I14-AI14 | AW14: =J14-AJ14 | AX14: =K14-AK14 | AY14: =L14-AL14 | ... BD14: =Q14-AQ14 | BE14: =SUMIF(AR14:BD14,"<0",AR14:BD14) | BF14: =IF(BE14<0,D14+BE14,D14) | BG14: =IF(IF(BF14<0,C14+BF14,C14)=0,"",IF(BF14<0,C14+BF14,C14)) | BJ14: 0 | BK14: 0 | BL14: 11
A15: 12100004555S/M | B15: High Coast Wind Cap | C15: 1 | E15: 0 | F15: 0 | G15: 0 | H15: 0 | I15: 0 | J15: 0 | K15: 0 | L15: 0 | M15: 0 | N15: 0 | O15: 0 | P15: 0 | Q15: 0 | AR15: =E15-AE15 | AS15: =F15-AF15 | AT15: =G15-AG15 | AU15: =H15-AH15 | AV15: =I15-AI15 | AW15: =J15-AJ15 | AX15: =K15-AK15 | AY15: =L15-AL15 | ... BD15: =Q15-AQ15 | BE15: =SUMIF(AR15:BD15,"<0",AR15:BD15) | BF15: =IF(BE15<0,D15+BE15,D15) | BG15: =IF(IF(BF15<0,C15+BF15,C15)=0,"",IF(BF15<0,C15+BF15,C15)) | BJ15: 0 | BK15: 0 | BL15: 12
A16: 12100004574-118L/XL | B16: High Coast Wind Cap | E16: 0 | F16: 0 | G16: 0 | H16: 0 | I16: 0 | J16: 0 | K16: 0 | L16: 0 | M16: 0 | N16: 0 | O16: 0 | P16: 0 | Q16: 0 | W16: 1 | AR16: =E16-AE16 | AS16: =F16-AF16 | AT16: =G16-AG16 | AU16: =H16-AH16 | AV16: =I16-AI16 | AW16: =J16-AJ16 | AX16: =K16-AK16 | AY16: =L16-AL16 | ... BD16: =Q16-AQ16 | BE16: =SUMIF(AR16:BD16,"<0",AR16:BD16) | BF16: =IF(BE16<0,D16+BE16,D16) | BG16: =IF(IF(BF16<0,C16+BF16,C16)=0,"",IF(BF16<0,C16+BF16,C16)) | BJ16: 0 | BK16: 0 | BL16: 13
A17: 12100004620-232L/XL | B17: High Coast Wind Cap | E17: 0 | F17: 0 | G17: 0 | H17: 0 | I17: 0 | J17: 0 | K17: 0 | L17: 0 | M17: 0 | N17: 0 | O17: 0 | P17: 0 | Q17: 0 | Y17: 2 | AR17: =E17-AE17 | AS17: =F17-AF17 | AT17: =G17-AG17 | AU17: =H17-AH17 | AV17: =I17-AI17 | AW17: =J17-AJ17 | AX17: =K17-AK17 | AY17: =L17-AL17 | ... BD17: =Q17-AQ17 | BE17: =SUMIF(AR17:BD17,"<0",AR17:BD17) | BF17: =IF(BE17<0,D17+BE17,D17) | BG17: =IF(IF(BF17<0,C17+BF17,C17)=0,"",IF(BF17<0,C17+BF17,C17)) | BJ17: 0 | BK17: 0 | BL17: 14
A18: 12100004620-232S/M | B18: High Coast Wind Cap | E18: 0 | F18: 0 | G18: 0 | H18: 0 | I18: 0 | J18: 0 | K18: 0 | L18: 0 | M18: 0 | N18: 0 | O18: 0 | P18: 0 | Q18: 0 | Y18: 1 | AR18: =E18-AE18 | AS18: =F18-AF18 | AT18: =G18-AG18 | AU18: =H18-AH18 | AV18: =I18-AI18 | AW18: =J18-AJ18 | AX18: =K18-AK18 | AY18: =L18-AL18 | ... BD18: =Q18-AQ18 | BE18: =SUMIF(AR18:BD18,"<0",AR18:BD18) | BF18: =IF(BE18<0,D18+BE18,D18) | BG18: =IF(IF(BF18<0,C18+BF18,C18)=0,"",IF(BF18<0,C18+BF18,C18)) | BJ18: 0 | BK18: 0 | BL18: 15
A19: 12100004620L/XL | B19: High Coast Wind Cap | E19: 0 | F19: 0 | G19: 0 | H19: 0 | I19: 0 | J19: 0 | K19: 0 | L19: 0 | M19: 0 | N19: 0 | O19: 0 | P19: 0 | Q19: 0 | X19: 1 | AR19: =E19-AE19 | AS19: =F19-AF19 | AT19: =G19-AG19 | AU19: =H19-AH19 | AV19: =I19-AI19 | AW19: =J19-AJ19 | AX19: =K19-AK19 | AY19: =L19-AL19 | ... BD19: =Q19-AQ19 | BE19: =SUMIF(AR19:BD19,"<0",AR19:BD19) | BF19: =IF(BE19<0,D19+BE19,D19) | BG19: =IF(IF(BF19<0,C19+BF19,C19)=0,"",IF(BF19<0,C19+BF19,C19)) | BJ19: 0 | BK19: 0 | BL19: 16
A20: 12100004620S/M | B20: High Coast Wind Cap | E20: 0 | F20: 0 | G20: 0 | H20: 0 | I20: 0 | J20: 0 | K20: 0 | L20: 0 | M20: 0 | N20: 0 | O20: 0 | P20: 0 | Q20: 0 | X20: 1 | AR20: =E20-AE20 | AS20: =F20-AF20 | AT20: =G20-AG20 | AU20: =H20-AH20 | AV20: =I20-AI20 | AW20: =J20-AJ20 | AX20: =K20-AK20 | AY20: =L20-AL20 | ... BD20: =Q20-AQ20 | BE20: =SUMIF(AR20:BD20,"<0",AR20:BD20) | BF20: =IF(BE20<0,D20+BE20,D20) | BG20: =IF(IF(BF20<0,C20+BF20,C20)=0,"",IF(BF20<0,C20+BF20,C20)) | BJ20: 0 | BK20: 0 | BL20: 17
A21: 12100006299X | B21: Fjallraven Heavy Beanie | E21: 0 | F21: 0 | G21: 0 | H21: 0 | I21: 0 | J21: 0 | K21: 0 | L21: 0 | M21: 0 | N21: 0 | O21: 0 | P21: 0 | Q21: 0 | U21: 1 | AR21: =E21-AE21 | AS21: =F21-AF21 | AT21: =G21-AG21 | AU21: =H21-AH21 | AV21: =I21-AI21 | AW21: =J21-AJ21 | AX21: =K21-AK21 | AY21: =L21-AL21 | ... BD21: =Q21-AQ21 | BE21: =SUMIF(AR21:BD21,"<0",AR21:BD21) | BF21: =IF(BE21<0,D21+BE21,D21) | BG21: =IF(IF(BF21<0,C21+BF21,C21)=0,"",IF(BF21<0,C21+BF21,C21)) | BJ21: 0 | BK21: 0 | BL21: 18
A22: 12100006514X | B22: Fjallraven Heavy Beanie | C22: 1 | E22: 0 | F22: 0 | G22: 0 | H22: 0 | I22: 0 | J22: 0 | K22: 0 | L22: 0 | M22: 0 | N22: 0 | O22: 0 | P22: 0 | Q22: 0 | U22: 1 | AR22: =E22-AE22 | AS22: =F22-AF22 | AT22: =G22-AG22 | AU22: =H22-AH22 | AV22: =I22-AI22 | AW22: =J22-AJ22 | AX22: =K22-AK22 | AY22: =L22-AL22 | ... BD22: =Q22-AQ22 | BE22: =SUMIF(AR22:BD22,"<0",AR22:BD22) | BF22: =IF(BE22<0,D22+BE22,D22) | BG22: =IF(IF(BF22<0,C22+BF22,C22)=0,"",IF(BF22<0,C22+BF22,C22)) | BJ22: 0 | BK22: 0 | BL22: 19
A23: 1220016455044/S | B23: Abisko Hybrid Trail Trs M | E23: 0 | F23: 0 | G23: 0 | H23: 0 | I23: 0 | J23: 0 | K23: 0 | L23: 0 | M23: 0 | N23: 0 | O23: 0 | P23: 0 | Q23: 0 | U23: 1 | AR23: =E23-AE23 | AS23: =F23-AF23 | AT23: =G23-AG23 | AU23: =H23-AH23 | AV23: =I23-AI23 | AW23: =J23-AJ23 | AX23: =K23-AK23 | AY23: =L23-AL23 | ... BD23: =Q23-AQ23 | BE23: =SUMIF(AR23:BD23,"<0",AR23:BD23) | BF23: =IF(BE23<0,D23+BE23,D23) | BG23: =IF(IF(BF23<0,C23+BF23,C23)=0,"",IF(BF23<0,C23+BF23,C23)) | BJ23: 0 | BK23: 0 | BL23: 20
A24: 12200190550L | B24: Bergtagen GTX Pro Trousers M | E24: 0 | F24: 0 | G24: 0 | H24: 0 | I24: 0 | J24: 0 | K24: 0 | L24: 0 | M24: 0 | N24: 0 | O24: 0 | P24: 0 | Q24: 0 | X24: 1 | AR24: =E24-AE24 | AS24: =F24-AF24 | AT24: =G24-AG24 | AU24: =H24-AH24 | AV24: =I24-AI24 | AW24: =J24-AJ24 | AX24: =K24-AK24 | AY24: =L24-AL24 | ... BD24: =Q24-AQ24 | BE24: =SUMIF(AR24:BD24,"<0",AR24:BD24) | BF24: =IF(BE24<0,D24+BE24,D24) | BG24: =IF(IF(BF24<0,C24+BF24,C24)=0,"",IF(BF24<0,C24+BF24,C24)) | BJ24: 0 | BK24: 0 | BL24: 21
A25: 12200190550M | B25: Bergtagen GTX Pro Trousers M | C25: 4 | E25: 0 | F25: 0 | G25: 0 | H25: 0 | I25: 0 | J25: 0 | K25: 0 | L25: 0 | M25: 0 | N25: 0 | O25: 0 | P25: 0 | Q25: 0 | U25: 1 | V25: 1 | X25: 1 | AR25: =E25-AE25 | AS25: =F25-AF25 | AT25: =G25-AG25 | AU25: =H25-AH25 | AV25: =I25-AI25 | AW25: =J25-AJ25 | AX25: =K25-AK25 | AY25: =L25-AL25 | ... BD25: =Q25-AQ25 | BE25: =SUMIF(AR25:BD25,"<0",AR25:BD25) | BF25: =IF(BE25<0,D25+BE25,D25) | BG25: =IF(IF(BF25<0,C25+BF25,C25)=0,"",IF(BF25<0,C25+BF25,C25)) | BJ25: 0 | BK25: 0 | BL25: 22
A26: 12200190550S | B26: Bergtagen GTX Pro Trousers M | C26: 1 | E26: 0 | F26: 0 | G26: 0 | H26: 0 | I26: 0 | J26: 0 | K26: 0 | L26: 0 | M26: 0 | N26: 0 | O26: 0 | P26: 0 | Q26: 0 | U26: 1 | V26: 1 | X26: 1 | AR26: =E26-AE26 | AS26: =F26-AF26 | AT26: =G26-AG26 | AU26: =H26-AH26 | AV26: =I26-AI26 | AW26: =J26-AJ26 | AX26: =K26-AK26 | AY26: =L26-AL26 | ... BD26: =Q26-AQ26 | BE26: =SUMIF(AR26:BD26,"<0",AR26:BD26) | BF26: =IF(BE26<0,D26+BE26,D26) | BG26: =IF(IF(BF26<0,C26+BF26,C26)=0,"",IF(BF26<0,C26+BF26,C26)) | BJ26: 0 | BK26: 0 | BL26: 23
A27: 12200190550XL | B27: Bergtagen GTX Pro Trousers M | E27: 0 | F27: 0 | G27: 0 | H27: 0 | I27: 0 | J27: 0 | K27: 0 | L27: 0 | M27: 0 | N27: 0 | O27: 0 | P27: 0 | Q27: 0 | U27: 1 | AR27: =E27-AE27 | AS27: =F27-AF27 | AT27: =G27-AG27 | AU27: =H27-AH27 | AV27: =I27-AI27 | AW27: =J27-AJ27 | AX27: =K27-AK27 | AY27: =L27-AL27 | ... BD27: =Q27-AQ27 | BE27: =SUMIF(AR27:BD27,"<0",AR27:BD27) | BF27: =IF(BE27<0,D27+BE27,D27) | BG27: =IF(IF(BF27<0,C27+BF27,C27)=0,"",IF(BF27<0,C27+BF27,C27)) | BJ27: 0 | BK27: 0 | BL27: 24
A28: 12200190550XS | B28: Bergtagen GTX Pro Trousers M | E28: 0 | F28: 0 | G28: 0 | H28: 0 | I28: 0 | J28: 0 | K28: 0 | L28: 0 | M28: 0 | N28: 0 | O28: 0 | P28: 0 | Q28: 0 | U28: 1 | X28: 1 | AR28: =E28-AE28 | AS28: =F28-AF28 | AT28: =G28-AG28 | AU28: =H28-AH28 | AV28: =I28-AI28 | AW28: =J28-AJ28 | AX28: =K28-AK28 | AY28: =L28-AL28 | ... BD28: =Q28-AQ28 | BE28: =SUMIF(AR28:BD28,"<0",AR28:BD28) | BF28: =IF(BE28<0,D28+BE28,D28) | BG28: =IF(IF(BF28<0,C28+BF28,C28)=0,"",IF(BF28<0,C28+BF28,C28)) | BJ28: 0 | BK28: 0 | BL28: 25
A29: 1220019755044 | B29: Hoja Hybrid Trousers M | D29: 5 | E29: 0 | F29: 0 | G29: 0 | H29: 0 | I29: 0 | J29: 0 | K29: 0 | L29: 0 | M29: 0 | N29: 0 | O29: 0 | P29: 0 | Q29: 0 | S29: 1 | U29: 1 | V29: 1 | W29: 1 | Y29: 1 | AA29: 1 | AC29: 1 | AR29: =E29-AE29 | AS29: =F29-AF29 | AT29: =G29-AG29 | AU29: =H29-AH29 | AV29: =I29-AI29 | AW29: =J29-AJ29 | AX29: =K29-AK29 | AY29: =L29-AL29 | ... BD29: =Q29-AQ29 | BE29: =SUMIF(AR29:BD29,"<0",AR29:BD29) | BF29: =IF(BE29<0,D29+BE29,D29) | BG29: =IF(IF(BF29<0,C29+BF29,C29)=0,"",IF(BF29<0,C29+BF29,C29)) | BJ29: 0 | BK29: 0 | BL29: 26
A30: 1220019755046 | B30: Hoja Hybrid Trousers M | C30: 1 | D30: 10 | E30: 0 | F30: 0 | G30: 0 | H30: 0 | I30: 0 | J30: 0 | K30: 0 | L30: 0 | M30: 0 | N30: 0 | O30: 0 | P30: 0 | Q30: 0 | S30: 1 | U30: 2 | V30: 1 | W30: 1 | X30: 1 | Y30: 1 | AA30: 1 | AC30: 1 | AR30: =E30-AE30 | AS30: =F30-AF30 | AT30: =G30-AG30 | AU30: =H30-AH30 | AV30: =I30-AI30 | AW30: =J30-AJ30 | AX30: =K30-AK30 | AY30: =L30-AL30 | ... BD30: =Q30-AQ30 | BE30: =SUMIF(AR30:BD30,"<0",AR30:BD30) | BF30: =IF(BE30<0,D30+BE30,D30) | BG30: =IF(IF(BF30<0,C30+BF30,C30)=0,"",IF(BF30<0,C30+BF30,C30)) | BJ30: 0 | BK30: 0 | BL30: 27
A31: 1220019755048 | B31: Hoja Hybrid Trousers M | D31: 7 | E31: 0 | F31: 0 | G31: 0 | H31: 0 | I31: 0 | J31: 0 | K31: 0 | L31: 0 | M31: 0 | N31: 0 | O31: 0 | P31: 0 | Q31: 0 | S31: 1 | U31: 1 | W31: 1 | X31: 1 | Y31: 1 | AA31: 1 | AC31: 1 | AI31: 1 | AR31: =E31-AE31 | AS31: =F31-AF31 | AT31: =G31-AG31 | AU31: =H31-AH31 | AV31: =I31-AI31 | AW31: =J31-AJ31 | AX31: =K31-AK31 | AY31: =L31-AL31 | ... BD31: =Q31-AQ31 | BE31: =SUMIF(AR31:BD31,"<0",AR31:BD31) | BF31: =IF(BE31<0,D31+BE31,D31) | BG31: =IF(IF(BF31<0,C31+BF31,C31)=0,"",IF(BF31<0,C31+BF31,C31)) | BJ31: 0 | BK31: 0 | BL31: 28
A32: 1220019755050 | B32: Hoja Hybrid Trousers M | D32: 3 | E32: 0 | F32: 0 | G32: 0 | H32: 0 | I32: 0 | J32: 0 | K32: 0 | L32: 0 | M32: 0 | N32: 0 | O32: 0 | P32: 0 | Q32: 0 | S32: 1 | U32: 1 | V32: 1 | W32: 1 | X32: 1 | Y32: 1 | AA32: 1 | AC32: 1 | AR32: =E32-AE32 | AS32: =F32-AF32 | AT32: =G32-AG32 | AU32: =H32-AH32 | AV32: =I32-AI32 | AW32: =J32-AJ32 | AX32: =K32-AK32 | AY32: =L32-AL32 | ... BD32: =Q32-AQ32 | BE32: =SUMIF(AR32:BD32,"<0",AR32:BD32) | BF32: =IF(BE32<0,D32+BE32,D32) | BG32: =IF(IF(BF32<0,C32+BF32,C32)=0,"",IF(BF32<0,C32+BF32,C32)) | BJ32: 0 | BK32: 0 | BL32: 29
A33: 1220019755052 | B33: Hoja Hybrid Trousers M | E33: 0 | F33: 0 | G33: 0 | H33: 0 | I33: 0 | J33: 0 | K33: 0 | L33: 0 | M33: 0 | N33: 0 | O33: 0 | P33: 0 | Q33: 0 | U33: 1 | V33: 1 | AR33: =E33-AE33 | AS33: =F33-AF33 | AT33: =G33-AG33 | AU33: =H33-AH33 | AV33: =I33-AI33 | AW33: =J33-AJ33 | AX33: =K33-AK33 | AY33: =L33-AL33 | ... BD33: =Q33-AQ33 | BE33: =SUMIF(AR33:BD33,"<0",AR33:BD33) | BF33: =IF(BE33<0,D33+BE33,D33) | BG33: =IF(IF(BF33<0,C33+BF33,C33)=0,"",IF(BF33<0,C33+BF33,C33)) | BJ33: 0 | BK33: 0 | BL33: 30
A34: 1220020755046 | B34: High Coast Pack Shorts M | C34: 1 | E34: 0 | F34: 0 | G34: 0 | H34: 0 | I34: 0 | J34: 0 | K34: 0 | L34: 0 | M34: 0 | N34: 0 | O34: 0 | P34: 0 | Q34: 0 | S34: 1 | U34: 1 | V34: 1 | W34: 1 | Y34: 1 | AA34: 1 | AB34: 1 | AC34: 1 | AR34: =E34-AE34 | AS34: =F34-AF34 | AT34: =G34-AG34 | AU34: =H34-AH34 | AV34: =I34-AI34 | AW34: =J34-AJ34 | AX34: =K34-AK34 | AY34: =L34-AL34 | ... BD34: =Q34-AQ34 | BE34: =SUMIF(AR34:BD34,"<0",AR34:BD34) | BF34: =IF(BE34<0,D34+BE34,D34) | BG34: =IF(IF(BF34<0,C34+BF34,C34)=0,"",IF(BF34<0,C34+BF34,C34)) | BJ34: 0 | BK34: 0 | BL34: 31
A35: 1220020755048 | B35: High Coast Pack Shorts M | C35: 1 | E35: 0 | F35: 0 | G35: 0 | H35: 0 | I35: 0 | J35: 0 | K35: 0 | L35: 0 | M35: 0 | N35: 0 | O35: 0 | P35: 0 | Q35: 0 | S35: 1 | U35: 1 | V35: 1 | W35: 1 | X35: 1 | Y35: 1 | AA35: 1 | AB35: 1 | AC35: 1 | AR35: =E35-AE35 | AS35: =F35-AF35 | AT35: =G35-AG35 | AU35: =H35-AH35 | AV35: =I35-AI35 | AW35: =J35-AJ35 | AX35: =K35-AK35 | AY35: =L35-AL35 | ... BD35: =Q35-AQ35 | BE35: =SUMIF(AR35:BD35,"<0",AR35:BD35) | BF35: =IF(BE35<0,D35+BE35,D35) | BG35: =IF(IF(BF35<0,C35+BF35,C35)=0,"",IF(BF35<0,C35+BF35,C35)) | BJ35: 0 | BK35: 0 | BL35: 32
A36: 1220020755050 | B36: High Coast Pack Shorts M | E36: 0 | F36: 0 | G36: 0 | H36: 0 | I36: 0 | J36: 0 | K36: 0 | L36: 0 | M36: 0 | N36: 0 | O36: 0 | P36: 0 | Q36: 0 | S36: 1 | U36: 1 | V36: 1 | W36: 1 | X36: 1 | Y36: 1 | AA36: 1 | AB36: 1 | AC36: 1 | AR36: =E36-AE36 | AS36: =F36-AF36 | AT36: =G36-AG36 | AU36: =H36-AH36 | AV36: =I36-AI36 | AW36: =J36-AJ36 | AX36: =K36-AK36 | AY36: =L36-AL36 | ... BD36: =Q36-AQ36 | BE36: =SUMIF(AR36:BD36,"<0",AR36:BD36) | BF36: =IF(BE36<0,D36+BE36,D36) | BG36: =IF(IF(BF36<0,C36+BF36,C36)=0,"",IF(BF36<0,C36+BF36,C36)) | BJ36: 0 | BK36: 0 | BL36: 33
A37: 1220020755052 | B37: High Coast Pack Shorts M | E37: 0 | F37: 0 | G37: 0 | H37: 0 | I37: 0 | J37: 0 | K37: 0 | L37: 0 | M37: 0 | N37: 0 | O37: 0 | P37: 0 | Q37: 0 | S37: 1 | U37: 1 | W37: 1 | AR37: =E37-AE37 | AS37: =F37-AF37 | AT37: =G37-AG37 | AU37: =H37-AH37 | AV37: =I37-AI37 | AW37: =J37-AJ37 | AX37: =K37-AK37 | AY37: =L37-AL37 | ... BD37: =Q37-AQ37 | BE37: =SUMIF(AR37:BD37,"<0",AR37:BD37) | BF37: =IF(BE37<0,D37+BE37,D37) | BG37: =IF(IF(BF37<0,C37+BF37,C37)=0,"",IF(BF37<0,C37+BF37,C37)) | BJ37: 0 | BK37: 0 | BL37: 34
A38: 1220020762546 | B38: High Coast Pack Shorts M | C38: 4 | E38: 0 | F38: 0 | G38: 0 | H38: 0 | I38: 0 | J38: 0 | K38: 0 | L38: 0 | M38: 0 | N38: 0 | O38: 0 | P38: 0 | Q38: 0 | S38: 1 | U38: 1 | V38: 1 | W38: 1 | X38: 1 | Y38: 1 | AA38: 1 | AB38: 1 | AC38: 1 | AR38: =E38-AE38 | AS38: =F38-AF38 | AT38: =G38-AG38 | AU38: =H38-AH38 | AV38: =I38-AI38 | AW38: =J38-AJ38 | AX38: =K38-AK38 | AY38: =L38-AL38 | ... BD38: =Q38-AQ38 | BE38: =SUMIF(AR38:BD38,"<0",AR38:BD38) | BF38: =IF(BE38<0,D38+BE38,D38) | BG38: =IF(IF(BF38<0,C38+BF38,C38)=0,"",IF(BF38<0,C38+BF38,C38)) | BJ38: 0 | BK38: 0 | BL38: 35
A39: 1220020762548 | B39: High Coast Pack Shorts M | E39: 0 | F39: 0 | G39: 0 | H39: 0 | I39: 0 | J39: 0 | K39: 0 | L39: 0 | M39: 0 | N39: 0 | O39: 0 | P39: 0 | Q39: 0 | S39: 1 | U39: 1 | V39: 1 | X39: 1 | Y39: 1 | AA39: 1 | AB39: 1 | AC39: 1 | AR39: =E39-AE39 | AS39: =F39-AF39 | AT39: =G39-AG39 | AU39: =H39-AH39 | AV39: =I39-AI39 | AW39: =J39-AJ39 | AX39: =K39-AK39 | AY39: =L39-AL39 | ... BD39: =Q39-AQ39 | BE39: =SUMIF(AR39:BD39,"<0",AR39:BD39) | BF39: =IF(BE39<0,D39+BE39,D39) | BG39: =IF(IF(BF39<0,C39+BF39,C39)=0,"",IF(BF39<0,C39+BF39,C39)) | BJ39: 0 | BK39: 0 | BL39: 36
A40: 1220020762550 | B40: High Coast Pack Shorts M | C40: 2 | E40: 0 | F40: 0 | G40: 0 | H40: 0 | I40: 0 | J40: 0 | K40: 0 | L40: 0 | M40: 0 | N40: 0 | O40: 0 | P40: 0 | Q40: 0 | S40: 1 | U40: 1 | W40: 1 | X40: 1 | Y40: 1 | AA40: 1 | AB40: 1 | AC40: 1 | AI40: 1 | AR40: =E40-AE40 | AS40: =F40-AF40 | AT40: =G40-AG40 | AU40: =H40-AH40 | AV40: =I40-AI40 | AW40: =J40-AJ40 | AX40: =K40-AK40 | AY40: =L40-AL40 | ... BD40: =Q40-AQ40 | BE40: =SUMIF(AR40:BD40,"<0",AR40:BD40) | BF40: =IF(BE40<0,D40+BE40,D40) | BG40: =IF(IF(BF40<0,C40+BF40,C40)=0,"",IF(BF40<0,C40+BF40,C40)) | BJ40: 0 | BK40: 0 | BL40: 37
...
